Workbook

Sheet README
A1: CAREER MARKET INTELLIGENCE — VERSION 3
A3: How this workbook is built
A4: This is the structure only — no bulk job data yet, on purpose. The workflow is:
A5: 1. Structure first (this file) → 2. Standardized categories (already built in) → 3. Enter jobs one by one → 4. Dashboard reveals patterns automatically → 5. Use patterns to decide what to learn next.
A7: What's new in V3
A8: - Optional Base / Bonus / Equity comp breakdown per job (01 - Job Database, cols BD-BR) instead of one lump Total Comp figure.
A9: - New 09 - Compensation Breakdown sheet: avg base/bonus/equity and split %, by role and by country.
A10: - New 10 - Skill x Role Heatmap: 🟩🟨🟥 visual version of the role x skill matrix from 04.
A11: - 05 - Country Intelligence: added INR 1Cr+ Count, USD 150k+ Count, and Visa Evidence Documented columns.
A12: - 02 - Dashboard: new Filtered View panel (bottom of sheet) — pick Role / Level / Country / Min Comp / Visa / Relocation and see matching-job KPIs update live.
A13: - 07 - My Skill Gap: added Target Level %, Gap vs Target, Priority vs Target, and a High-Paying Jobs Demand % column so you can compare a skill's overall market frequency against its frequency in 50L+/100k+ roles specifically.
A14: - 08 - Trend Over Time: added Avg Total Comp, International Jobs %, and Top Role per quarter.
... A61: Skill list (32 skills) is fixed by design so every skill can be tracked with simple, error-free formulas — extending it later means adding a column in 01 - Job Database and mirroring it across sheets 03/04/05/07/08.

Sheet 01 - Job Database
A1: 01 · JOB DATABASE — one job posting = one row. Enter data only in white cells; colored/formula cells are automatic.
A2: Job ID | B2: Date Found | C2: Company | D2: Role Title (Raw) | E2: Standardized Role | F2: Level | G2: Country | H2: City | I2: Location Type | J2: Visa Sponsorship | K2: Relocation Support | L2: Currency | M2: Salary Min | N2: Salary Max | O2: Total Comp Min (INR Lakhs) | P2: Total Comp Max (INR Lakhs) | Q2: Total Comp Min (USD) | R2: Total Comp Max (USD) | S2: Meets INR 50L+ | T2: Meets USD 100k+ | U2: Discovery URL | V2: Notes | W2: Exclude From Analysis | X2: C++ | Y2: Python | Z2: Java | AA2: Go | AB2: Rust | AC2: JavaScript/TypeScript | AD2: C | AE2: SQL | AF2: Linux | AG2: Operating Systems | AH2: Multithreading & Concurrency | AI2: Networking | AJ2: Distributed Systems | AK2: Compilers | AL2: AWS | AM2: Azure | AN2: GCP | AO2: Kubernetes | AP2: Docker | AQ2: Terraform | AR2: CI/CD | AS2: Data Structures & Algorithms | AT2: Machine Learning | AU2: Deep Learning | AV2: PyTorch/TensorFlow | AW2: LLMs / NLP | AX2: CUDA / GPU Programming | AY2: Big Data (Spark/Hadoop) | AZ2: System Design | BA2: Microservices / API Design | BB2: Security / Cryptography | BC2: Testing / QA | BD2: Base Comp Min | BE2: Base Comp Max | BF2: Bonus Min (Annual) | BG2: Bonus Max (Annual) | BH2: Equity Min (Annual, Amortized) | BI2: Equity Max (Annual, Amortized) | BJ2: Comp Breakdown Entered? | BK2: Base Min (INR Lakhs) | BL2: Base Max (INR Lakhs) | BM2: Bonus Min (INR Lakhs) | BN2: Bonus Max (INR Lakhs) | BO2: Equity Min (INR Lakhs) | BP2: Equity Max (INR Lakhs) | BQ2: Visa Sponsorship Evidence / Source | BR2: Relocation Evidence / Source | BS2: Meets INR 20L+ | BT2: Meets INR 30L+ | BU2: Meets INR 75L+ | BV2: Meets INR 1Cr+ | BW2: Meets INR 1.5Cr+ | BX2: Meets INR 2Cr+ | BY2: Meets USD 150k+ | BZ2: Meets USD 200k+ | CA2: Meets USD 250k+ | CB2: Meets USD 300k+ | CC2: Job Source | CD2: Job Freshness | CE2: Intl Candidate Viability (India->USA) | CF2: Visa Sponsorship Data Type | CG2: Relocation Data Type | CH2: Source Type | CI2: Original / Official Source | CJ2: Official Job URL | CK2: Data Source / Evidence | CL2: Additional Skills Detected (Unmapped) | CM2: HTML | CN2: CSS | CO2: MySQL | CP2: Git | CQ2: PostgreSQL | CR2: Jenkins | CS2: Selenium | CT2: Bamboo | CU2: Argo | CV2: Playwright | CW2: Cypress
A3: 0 | B3: 46235 | C3: Google | D3: Software Engineer III, Backend Infrastructure | E3: Backend Engineer | F3: Mid (2-5y) | G3: USA | H3: Mountain View, CA | I3: Onsite | J3: Yes | K3: Yes | L3: USD | M3: 185000 | N3: 230000 | O3: =IFERROR(IF(M3="","",M3*INDEX('00 - Lists'!$M$2:$M$11,MATCH(L3,'00 - Lists'!$L$2:$L$11,0))/100000),"") -> 160.95 | P3: =IFERROR(IF(N3="","",N3*INDEX('00 - Lists'!$M$2:$M$11,MATCH(L3,'00 - Lists'!$L$2:$L$11,0))/100000),"") -> 200.1 | Q3: =IFERROR(IF(M3="","",M3*INDEX('00 - Lists'!$N$2:$N$11,MATCH(L3,'00 - Lists'!$L$2:$L$11,0))),"") -> 185000 | R3: =IFERROR(IF(N3="","",N3*INDEX('00 - Lists'!$N$2:$N$11,MATCH(L3,'00 - Lists'!$L$2:$L$11,0))),"") -> 230000 | S3: =IF(O3="","",IF(O3>=50,"Yes","No")) -> Yes | T3: =IF(Q3="","",IF(Q3>=100000,"Yes","No")) -> Yes | U3: https://careers.google.com/jobs/... | V3: EXAMPLE ROW — delete or overwrite. Shows expected format. | W3: Yes | X3: Yes | Y3: No | Z3: No | AA3: Yes | AB3: No | AC3: No | AD3: No | AE3: No | AF3: Yes | AG3: No | AH3: No | AI3: Yes | AJ3: Yes | AK3: No | AL3: No | AM3: No | AN3: No | AO3: Yes | AP3: No | AQ3: No | AR3: No | AS3: Yes | AT3: No | AU3: No | AV3: No | AW3: No | AX3: No | AY3: No | AZ3: Yes | BA3: No | BB3: No | BC3: No | BD3: 165000 | BE3: 195000 | BF3: 15000 | BG3: 20000 | BH3: 20000 | BI3: 25000 | BJ3: =IF(OR($BD3<>"",$BF3<>"",$BH3<>""),"Yes","No") -> Yes | BK3: =IFERROR(IF(BD3="","",BD3*INDEX('00 - Lists'!$M$2:$M$11,MATCH(L3,'00 - Lists'!$L$2:$L$11,0))/100000),"") -> 143.55 | BL3: =IFERROR(IF(BE3="","",BE3*INDEX('00 - Lists'!$M$2:$M$11,MATCH(L3,'00 - Lists'!$L$2:$L$11,0))/100000),"") -> 169.65 | BM3: =IFERROR(IF(BF3="","",BF3*INDEX('00 - Lists'!$M$2:$M$11,MATCH(L3,'00 - Lists'!$L$2:$L$11,0))/100000),"") -> 13.05 | BN3: =IFERROR(IF(BG3="","",BG3*INDEX('00 - Lists'!$M$2:$M$11,MATCH(L3,'00 - Lists'!$L$2:$L$11,0))/100000),"") -> 17.4 | BO3: =IFERROR(IF(BH3="","",BH3*INDEX('00 - Lists'!$M$2:$M$11,MATCH(L3,'00 - Lists'!$L$2:$L$11,0))/100000),"") -> 17.4 | BP3: =IFERROR(IF(BI3="","",BI3*INDEX('00 - Lists'!$M$2:$M$11,MATCH(L3,'00 - Lists'!$L$2:$L$11,0))/100000),"") -> 21.75 | BQ3: Sample: Google careers page states H-1B sponsorship available for eligible roles | BR3: Sample: relocation package confirmed in written offer | BS3: =IF(O3="","",IF(O3>=20,"Yes","No")) -> Yes | BT3: =IF(O3="","",IF(O3>=30,"Yes","No")) -> Yes | BU3: =IF(O3="","",IF(O3>=75,"Yes","No")) -> Yes | BV3: =IF(O3="","",IF(O3>=100,"Yes","No")) -> Yes | BW3: =IF(O3="","",IF(O3>=150,"Yes","No")) -> Yes | BX3: =IF(O3="","",IF(O3>=200,"Yes","No")) -> No | BY3: =IF(Q3="","",IF(Q3>=150000,"Yes","No")) -> Yes | BZ3: =IF(Q3="","",IF(Q3>=200000,"Yes","No")) -> No | CA3: =IF(Q3="","",IF(Q3>=250000,"Yes","No")) -> No | CB3: =IF(Q3="","",IF(Q3>=300000,"Yes","No")) -> No | CC3: LinkedIn | CD3: =IF(B3="","",IF(TODAY()-B3<=7,"🟢 0-7d",IF(TODAY()-B3<=30,"🟡 8-30d",IF(TODAY()-B3<=60,"🟠 31-60d","🔴 60d+")))) -> 🟡 8-30d | CE3: =IF(G3="","",IF(G3<>"USA","N/A - Not USA Role",IF(J3="Yes",IF(OR(F3="Intern",F3="New Grad"),"🟡 Possible","🟢 Strong"),IF(J3="No","🔴 Difficult","⚪ Unknown")))) -> 🟢 Strong | CF3: Observed | CG3: Observed | CH3: Company Careers | CI3: Google Careers | CJ3: https://careers.google.com/jobs/... | CK3: Sample: job discovered on LinkedIn; salary confirmed on Google careers posting; visa evidence from Google careers page
A4: =IF($C4="","",ROW()-3) -> 1 | B4: 2026-08-22 | C4: Amazon | D4: Software Development Engineer, Amazon Optics | E4: Software Engineer | F4: Unknown | G4: USA | H4: Multiple (Annapolis Junction, New York, Arlington, Herndon) | I4: Unknown | J4: Unknown | K4: Unknown | L4: USD | M4: 143700.00 | N4: 213800.00 | O4: =IFERROR(IF(M4="","",M4*INDEX('00 - Lists'!$M$2:$M$11,MATCH(L4,'00 - Lists'!$L$2:$L$11,0))/100000),"") -> 125.019 | P4: =IFERROR(IF(N4="","",N4*INDEX('00 - Lists'!$M$2:$M$11,MATCH(L4,'00 - Lists'!$L$2:$L$11,0))/100000),"") -> 186.006 | Q4: =IFERROR(IF(M4="","",M4*INDEX('00 - Lists'!$N$2:$N$11,MATCH(L4,'00 - Lists'!$L$2:$L$11,0))),"") -> 143700 | R4: =IFERROR(IF(N4="","",N4*INDEX('00 - Lists'!$N$2:$N$11,MATCH(L4,'00 - Lists'!$L$2:$L$11,0))),"") -> 213800 | S4: =IF(O4="","",IF(O4>=50,"Yes","No")) -> Yes | T4: =IF(Q4="","",IF(Q4>=100000,"Yes","No")) -> Yes | U4: https://www.amazon.jobs/en/jobs/10511479/software-development-engineer-amazon-optics | V4: Base salary ranges vary by location: Annapolis Junction, MD / Arlington, VA / Herndon, VA: 143,700 - 194,400 USD; New York, NY: 158,100 - 213,800 USD. | W4: No | X4: Yes | Y4: Unknown | Z4: Yes | AA4: No | AB4: No | AC4: No | AD4: No | AE4: No | AF4: Unknown | AG4: Unknown | AH4: Yes | AI4: Unknown | AJ4: Yes | AK4: No | AL4: Yes | AM4: No | AN4: No | AO4: No | AP4: Unknown | AQ4: Unknown | AR4: Unknown | AS4: Unknown | AT4: Yes | AU4: Yes | AV4: Unknown | AW4: Yes | AX4: Unknown | AY4: No | AZ4: Yes | BA4: Yes | BB4: Yes | BC4: Yes | BD4: 143700.00 | BE4: 213800.00 | BJ4: =IF(OR($BD4<>"",$BF4<>"",$BH4<>""),"Yes","No") -> Yes | BK4: =IFERROR(IF(BD4="","",BD4*INDEX('00 - Lists'!$M$2:$M$11,MATCH(L4,'00 - Lists'!$L$2:$L$11,0))/100000),"") -> 125.019 | BL4: =IFERROR(IF(BE4="","",BE4*INDEX('00 - Lists'!$M$2:$M$11,MATCH(L4,'00 - Lists'!$L$2:$L$11,0))/100000),"") -> 186.006 | BM4: =IFERROR(IF(BF4="","",BF4*INDEX('00 - Lists'!$M$2:$M$11,MATCH(L4,'00 - Lists'!$L$2:$L$11,0))/100000),"") | BN4: =IFERROR(IF(BG4="","",BG4*INDEX('00 - Lists'!$M$2:$M$11,MATCH(L4,'00 - Lists'!$L$2:$L$11,0))/100000),"") | BO4: =IFERROR(IF(BH4="","",BH4*INDEX('00 - Lists'!$M$2:$M$11,MATCH(L4,'00 - Lists'!$L$2:$L$11,0))/100000),"") | BP4: =IFERROR(IF(BI4="","",BI4*INDEX('00 - Lists'!$M$2:$M$11,MATCH(L4,'00 - Lists'!$L$2:$L$11,0))/100000),"") | BS4: =IF(O4="","",IF(O4>=20,"Yes","No")) -> Yes | BT4: =IF(O4="","",IF(O4>=30,"Yes","No")) -> Yes | BU4: =IF(O4="","",IF(O4>=75,"Yes","No")) -> Yes | BV4: =IF(O4="","",IF(O4>=100,"Yes","No")) -> Yes | BW4: =IF(O4="","",IF(O4>=150,"Yes","No")) -> No | BX4: =IF(O4="","",IF(O4>=200,"Yes","No")) -> No | BY4: =IF(Q4="","",IF(Q4>=150000,"Yes","No")) -> No | BZ4: =IF(Q4="","",IF(Q4>=200000,"Yes","No")) -> No | CA4: =IF(Q4="","",IF(Q4>=250000,"Yes","No")) -> No | CB4: =IF(Q4="","",IF(Q4>=300000,"Yes","No")) -> No | CC4: Amazon.jobs | CD4: =IF(B4="","",IF(TODAY()-B4<=7,"🟢 0-7d",IF(TODAY()-B4<=30,"🟡 8-30d",IF(TODAY()-B4<=60,"🟠 31-60d","🔴 60d+")))) -> 🟢 0-7d | CE4: =IF(G4="","",IF(G4<>"USA","N/A - Not USA Role",IF(J4="Yes",IF(OR(F4="Intern",F4="New Grad"),"🟡 Possible","🟢 Strong"),IF(J4="No","🔴 Difficult","⚪ Unknown")))) -> ⚪ Unknown | CH4: Company Website | CI4: Amazon | CJ4: https://www.amazon.jobs/en/jobs/10511479/software-development-engineer-amazon-optics | CK4: Amazon Job Posting | CL4: C#
A5: =IF($C5="","",ROW()-3) | O5: =IFERROR(IF(M5="","",M5*INDEX('00 - Lists'!$M$2:$M$11,MATCH(L5,'00 - Lists'!$L$2:$L$11,0))/100000),"") | P5: =IFERROR(IF(N5="","",N5*INDEX('00 - Lists'!$M$2:$M$11,MATCH(L5,'00 - Lists'!$L$2:$L$11,0))/100000),"") | Q5: =IFERROR(IF(M5="","",M5*INDEX('00 - Lists'!$N$2:$N$11,MATCH(L5,'00 - Lists'!$L$2:$L$11,0))),"") | R5: =IFERROR(IF(N5="","",N5*INDEX('00 - Lists'!$N$2:$N$11,MATCH(L5,'00 - Lists'!$L$2:$L$11,0))),"") | S5: =IF(O5="","",IF(O5>=50,"Yes","No")) | T5: =IF(Q5="","",IF(Q5>=100000,"Yes","No")) | BJ5: =IF(OR($BD5<>"",$BF5<>"",$BH5<>""),"Yes","No") -> No | BK5: =IFERROR(IF(BD5="","",BD5*INDEX('00 - Lists'!$M$2:$M$11,MATCH(L5,'00 - Lists'!$L$2:$L$11,0))/100000),"") | BL5: =IFERROR(IF(BE5="","",BE5*INDEX('00 - Lists'!$M$2:$M$11,MATCH(L5,'00 - Lists'!$L$2:$L$11,0))/100000),"") | BM5: =IFERROR(IF(BF5="","",BF5*INDEX('00 - Lists'!$M$2:$M$11,MATCH(L5,'00 - Lists'!$L$2:$L$11,0))/100000),"") | BN5: =IFERROR(IF(BG5="","",BG5*INDEX('00 - Lists'!$M$2:$M$11,MATCH(L5,'00 - Lists'!$L$2:$L$11,0))/100000),"") | BO5: =IFERROR(IF(BH5="","",BH5*INDEX('00 - Lists'!$M$2:$M$11,MATCH(L5,'00 - Lists'!$L$2:$L$11,0))/100000),"") | BP5: =IFERROR(IF(BI5="","",BI5*INDEX('00 - Lists'!$M$2:$M$11,MATCH(L5,'00 - Lists'!$L$2:$L$11,0))/100000),"") | BS5: =IF(O5="","",IF(O5>=20,"Yes","No")) | BT5: =IF(O5="","",IF(O5>=30,"Yes","No")) | BU5: =IF(O5="","",IF(O5>=75,"Yes","No")) | BV5: =IF(O5="","",IF(O5>=100,"Yes","No")) | BW5: =IF(O5="","",IF(O5>=150,"Yes","No")) | BX5: =IF(O5="","",IF(O5>=200,"Yes","No")) | BY5: =IF(Q5="","",IF(Q5>=150000,"Yes","No")) | BZ5: =IF(Q5="","",IF(Q5>=200000,"Yes","No")) | CA5: =IF(Q5="","",IF(Q5>=250000,"Yes","No")) | CB5: =IF(Q5="","",IF(Q5>=300000,"Yes","No")) | CD5: =IF(B5="","",IF(TODAY()-B5<=7,"🟢 0-7d",IF(TODAY()-B5<=30,"🟡 8-30d",IF(TODAY()-B5<=60,"🟠 31-60d","🔴 60d+")))) | CE5: =IF(G5="","",IF(G5<>"USA","N/A - Not USA Role",IF(J5="Yes",IF(OR(F5="Intern",F5="New Grad"),"🟡 Possible","🟢 Strong"),IF(J5="No","🔴 Difficult","⚪ Unknown"))))
A6: =IF($C6="","",ROW()-3) | O6: =IFERROR(IF(M6="","",M6*INDEX('00 - Lists'!$M$2:$M$11,MATCH(L6,'00 - Lists'!$L$2:$L$11,0))/100000),"") | P6: =IFERROR(IF(N6="","",N6*INDEX('00 - Lists'!$M$2:$M$11,MATCH(L6,'00 - Lists'!$L$2:$L$11,0))/100000),"") | Q6: =IFERROR(IF(M6="","",M6*INDEX('00 - Lists'!$N$2:$N$11,MATCH(L6,'00 - Lists'!$L$2:$L$11,0))),"") | R6: =IFERROR(IF(N6="","",N6*INDEX('00 - Lists'!$N$2:$N$11,MATCH(L6,'00 - Lists'!$L$2:$L$11,0))),"") | S6: =IF(O6="","",IF(O6>=50,"Yes","No")) | T6: =IF(Q6="","",IF(Q6>=100000,"Yes","No")) | BJ6: =IF(OR($BD6<>"",$BF6<>"",$BH6<>""),"Yes","No") -> No | BK6: =IFERROR(IF(BD6="","",BD6*INDEX('00 - Lists'!$M$2:$M$11,MATCH(L6,'00 - Lists'!$L$2:$L$11,0))/100000),"") | BL6: =IFERROR(IF(BE6="","",BE6*INDEX('00 - Lists'!$M$2:$M$11,MATCH(L6,'00 - Lists'!$L$2:$L$11,0))/100000),"") | BM6: =IFERROR(IF(BF6="","",BF6*INDEX('00 - Lists'!$M$2:$M$11,MATCH(L6,'00 - Lists'!$L$2:$L$11,0))/100000),"") | BN6: =IFERROR(IF(BG6="","",BG6*INDEX('00 - Lists'!$M$2:$M$11,MATCH(L6,'00 - Lists'!$L$2:$L$11,0))/100000),"") | BO6: =IFERROR(IF(BH6="","",BH6*INDEX('00 - Lists'!$M$2:$M$11,MATCH(L6,'00 - Lists'!$L$2:$L$11,0))/100000),"") | BP6: =IFERROR(IF(BI6="","",BI6*INDEX('00 - Lists'!$M$2:$M$11,MATCH(L6,'00 - Lists'!$L$2:$L$11,0))/100000),"") | BS6: =IF(O6="","",IF(O6>=20,"Yes","No")) | BT6: =IF(O6="","",IF(O6>=30,"Yes","No")) | BU6: =IF(O6="","",IF(O6>=75,"Yes","No")) | BV6: =IF(O6="","",IF(O6>=100,"Yes","No")) | BW6: =IF(O6="","",IF(O6>=150,"Yes","No")) | BX6: =IF(O6="","",IF(O6>=200,"Yes","No")) | BY6: =IF(Q6="","",IF(Q6>=150000,"Yes","No")) | BZ6: =IF(Q6="","",IF(Q6>=200000,"Yes","No")) | CA6: =IF(Q6="","",IF(Q6>=250000,"Yes","No")) | CB6: =IF(Q6="","",IF(Q6>=300000,"Yes","No")) | CD6: =IF(B6="","",IF(TODAY()-B6<=7,"🟢 0-7d",IF(TODAY()-B6<=30,"🟡 8-30d",IF(TODAY()-B6<=60,"🟠 31-60d","🔴 60d+")))) | CE6: =IF(G6="","",IF(G6<>"USA","N/A - Not USA Role",IF(J6="Yes",IF(OR(F6="Intern",F6="New Grad"),"🟡 Possible","🟢 Strong"),IF(J6="No","🔴 Difficult","⚪ Unknown"))))
A7: =IF($C7="","",ROW()-3) | O7: =IFERROR(IF(M7="","",M7*INDEX('00 - Lists'!$M$2:$M$11,MATCH(L7,'00 - Lists'!$L$2:$L$11,0))/100000),"") | P7: =IFERROR(IF(N7="","",N7*INDEX('00 - Lists'!$M$2:$M$11,MATCH(L7,'00 - Lists'!$L$2:$L$11,0))/100000),"") | Q7: =IFERROR(IF(M7="","",M7*INDEX('00 - Lists'!$N$2:$N$11,MATCH(L7,'00 - Lists'!$L$2:$L$11,0))),"") | R7: =IFERROR(IF(N7="","",N7*INDEX('00 - Lists'!$N$2:$N$11,MATCH(L7,'00 - Lists'!$L$2:$L$11,0))),"") | S7: =IF(O7="","",IF(O7>=50,"Yes","No")) | T7: =IF(Q7="","",IF(Q7>=100000,"Yes","No")) | BJ7: =IF(OR($BD7<>"",$BF7<>"",$BH7<>""),"Yes","No") -> No | BK7: =IFERROR(IF(BD7="","",BD7*INDEX('00 - Lists'!$M$2:$M$11,MATCH(L7,'00 - Lists'!$L$2:$L$11,0))/100000),"") | BL7: =IFERROR(IF(BE7="","",BE7*INDEX('00 - Lists'!$M$2:$M$11,MATCH(L7,'00 - Lists'!$L$2:$L$11,0))/100000),"") | BM7: =IFERROR(IF(BF7="","",BF7*INDEX('00 - Lists'!$M$2:$M$11,MATCH(L7,'00 - Lists'!$L$2:$L$11,0))/100000),"") | BN7: =IFERROR(IF(BG7="","",BG7*INDEX('00 - Lists'!$M$2:$M$11,MATCH(L7,'00 - Lists'!$L$2:$L$11,0))/100000),"") | BO7: =IFERROR(IF(BH7="","",BH7*INDEX('00 - Lists'!$M$2:$M$11,MATCH(L7,'00 - Lists'!$L$2:$L$11,0))/100000),"") | BP7: =IFERROR(IF(BI7="","",BI7*INDEX('00 - Lists'!$M$2:$M$11,MATCH(L7,'00 - Lists'!$L$2:$L$11,0))/100000),"") | BS7: =IF(O7="","",IF(O7>=20,"Yes","No")) | BT7: =IF(O7="","",IF(O7>=30,"Yes","No")) | BU7: =IF(O7="","",IF(O7>=75,"Yes","No")) | BV7: =IF(O7="","",IF(O7>=100,"Yes","No")) | BW7: =IF(O7="","",IF(O7>=150,"Yes","No")) | BX7: =IF(O7="","",IF(O7>=200,"Yes","No")) | BY7: =IF(Q7="","",IF(Q7>=150000,"Yes","No")) | BZ7: =IF(Q7="","",IF(Q7>=200000,"Yes","No")) | CA7: =IF(Q7="","",IF(Q7>=250000,"Yes","No")) | CB7: =IF(Q7="","",IF(Q7>=300000,"Yes","No")) | CD7: =IF(B7="","",IF(TODAY()-B7<=7,"🟢 0-7d",IF(TODAY()-B7<=30,"🟡 8-30d",IF(TODAY()-B7<=60,"🟠 31-60d","🔴 60d+")))) | CE7: =IF(G7="","",IF(G7<>"USA","N/A - Not USA Role",IF(J7="Yes",IF(OR(F7="Intern",F7="New Grad"),"🟡 Possible","🟢 Strong"),IF(J7="No","🔴 Difficult","⚪ Unknown"))))
A8: =IF($C8="","",ROW()-3) | O8: =IFERROR(IF(M8="","",M8*INDEX('00 - Lists'!$M$2:$M$11,MATCH(L8,'00 - Lists'!$L$2:$L$11,0))/100000),"") | P8: =IFERROR(IF(N8="","",N8*INDEX('00 - Lists'!$M$2:$M$11,MATCH(L8,'00 - Lists'!$L$2:$L$11,0))/100000),"") | Q8: =IFERROR(IF(M8="","",M8*INDEX('00 - Lists'!$N$2:$N$11,MATCH(L8,'00 - Lists'!$L$2:$L$11,0))),"") | R8: =IFERROR(IF(N8="","",N8*INDEX('00 - Lists'!$N$2:$N$11,MATCH(L8,'00 - Lists'!$L$2:$L$11,0))),"") | S8: =IF(O8="","",IF(O8>=50,"Yes","No")) | T8: =IF(Q8="","",IF(Q8>=100000,"Yes","No")) | BJ8: =IF(OR($BD8<>"",$BF8<>"",$BH8<>""),"Yes","No") -> No | BK8: =IFERROR(IF(BD8="","",BD8*INDEX('00 - Lists'!$M$2:$M$11,MATCH(L8,'00 - Lists'!$L$2:$L$11,0))/100000),"") | BL8: =IFERROR(IF(BE8="","",BE8*INDEX('00 - Lists'!$M$2:$M$11,MATCH(L8,'00 - Lists'!$L$2:$L$11,0))/100000),"") | BM8: =IFERROR(IF(BF8="","",BF8*INDEX('00 - Lists'!$M$2:$M$11,MATCH(L8,'00 - Lists'!$L$2:$L$11,0))/100000),"") | BN8: =IFERROR(IF(BG8="","",BG8*INDEX('00 - Lists'!$M$2:$M$11,MATCH(L8,'00 - Lists'!$L$2:$L$11,0))/100000),"") | BO8: =IFERROR(IF(BH8="","",BH8*INDEX('00 - Lists'!$M$2:$M$11,MATCH(L8,'00 - Lists'!$L$2:$L$11,0))/100000),"") | BP8: =IFERROR(IF(BI8="","",BI8*INDEX('00 - Lists'!$M$2:$M$11,MATCH(L8,'00 - Lists'!$L$2:$L$11,0))/100000),"") | BS8: =IF(O8="","",IF(O8>=20,"Yes","No")) | BT8: =IF(O8="","",IF(O8>=30,"Yes","No")) | BU8: =IF(O8="","",IF(O8>=75,"Yes","No")) | BV8: =IF(O8="","",IF(O8>=100,"Yes","No")) | BW8: =IF(O8="","",IF(O8>=150,"Yes","No")) | BX8: =IF(O8="","",IF(O8>=200,"Yes","No")) | BY8: =IF(Q8="","",IF(Q8>=150000,"Yes","No")) | BZ8: =IF(Q8="","",IF(Q8>=200000,"Yes","No")) | CA8: =IF(Q8="","",IF(Q8>=250000,"Yes","No")) | CB8: =IF(Q8="","",IF(Q8>=300000,"Yes","No")) | CD8: =IF(B8="","",IF(TODAY()-B8<=7,"🟢 0-7d",IF(TODAY()-B8<=30,"🟡 8-30d",IF(TODAY()-B8<=60,"🟠 31-60d","🔴 60d+")))) | CE8: =IF(G8="","",IF(G8<>"USA","N/A - Not USA Role",IF(J8="Yes",IF(OR(F8="Intern",F8="New Grad"),"🟡 Possible","🟢 Strong"),IF(J8="No","🔴 Difficult","⚪ Unknown"))))
A9: =IF($C9="","",ROW()-3) | O9: =IFERROR(IF(M9="","",M9*INDEX('00 - Lists'!$M$2:$M$11,MATCH(L9,'00 - Lists'!$L$2:$L$11,0))/100000),"") | P9: =IFERROR(IF(N9="","",N9*INDEX('00 - Lists'!$M$2:$M$11,MATCH(L9,'00 - Lists'!$L$2:$L$11,0))/100000),"") | Q9: =IFERROR(IF(M9="","",M9*INDEX('00 - Lists'!$N$2:$N$11,MATCH(L9,'00 - Lists'!$L$2:$L$11,0))),"") | R9: =IFERROR(IF(N9="","",N9*INDEX('00 - Lists'!$N$2:$N$11,MATCH(L9,'00 - Lists'!$L$2:$L$11,0))),"") | S9: =IF(O9="","",IF(O9>=50,"Yes","No")) | T9: =IF(Q9="","",IF(Q9>=100000,"Yes","No")) | BJ9: =IF(OR($BD9<>"",$BF9<>"",$BH9<>""),"Yes","No") -> No | BK9: =IFERROR(IF(BD9="","",BD9*INDEX('00 - Lists'!$M$2:$M$11,MATCH(L9,'00 - Lists'!$L$2:$L$11,0))/100000),"") | BL9: =IFERROR(IF(BE9="","",BE9*INDEX('00 - Lists'!$M$2:$M$11,MATCH(L9,'00 - Lists'!$L$2:$L$11,0))/100000),"") | BM9: =IFERROR(IF(BF9="","",BF9*INDEX('00 - Lists'!$M$2:$M$11,MATCH(L9,'00 - Lists'!$L$2:$L$11,0))/100000),"") | BN9: =IFERROR(IF(BG9="","",BG9*INDEX('00 - Lists'!$M$2:$M$11,MATCH(L9,'00 - Lists'!$L$2:$L$11,0))/100000),"") | BO9: =IFERROR(IF(BH9="","",BH9*INDEX('00 - Lists'!$M$2:$M$11,MATCH(L9,'00 - Lists'!$L$2:$L$11,0))/100000),"") | BP9: =IFERROR(IF(BI9="","",BI9*INDEX('00 - Lists'!$M$2:$M$11,MATCH(L9,'00 - Lists'!$L$2:$L$11,0))/100000),"") | BS9: =IF(O9="","",IF(O9>=20,"Yes","No")) | BT9: =IF(O9="","",IF(O9>=30,"Yes","No")) | BU9: =IF(O9="","",IF(O9>=75,"Yes","No")) | BV9: =IF(O9="","",IF(O9>=100,"Yes","No")) | BW9: =IF(O9="","",IF(O9>=150,"Yes","No")) | BX9: =IF(O9="","",IF(O9>=200,"Yes","No")) | BY9: =IF(Q9="","",IF(Q9>=150000,"Yes","No")) | BZ9: =IF(Q9="","",IF(Q9>=200000,"Yes","No")) | CA9: =IF(Q9="","",IF(Q9>=250000,"Yes","No")) | CB9: =IF(Q9="","",IF(Q9>=300000,"Yes","No")) | CD9: =IF(B9="","",IF(TODAY()-B9<=7,"🟢 0-7d",IF(TODAY()-B9<=30,"🟡 8-30d",IF(TODAY()-B9<=60,"🟠 31-60d","🔴 60d+")))) | CE9: =IF(G9="","",IF(G9<>"USA","N/A - Not USA Role",IF(J9="Yes",IF(OR(F9="Intern",F9="New Grad"),"🟡 Possible","🟢 Strong"),IF(J9="No","🔴 Difficult","⚪ Unknown"))))
A10: =IF($C10="","",ROW()-3) | O10: =IFERROR(IF(M10="","",M10*INDEX('00 - Lists'!$M$2:$M$11,MATCH(L10,'00 - Lists'!$L$2:$L$11,0))/100000),"") | P10: =IFERROR(IF(N10="","",N10*INDEX('00 - Lists'!$M$2:$M$11,MATCH(L10,'00 - Lists'!$L$2:$L$11,0))/100000),"") | Q10: =IFERROR(IF(M10="","",M10*INDEX('00 - Lists'!$N$2:$N$11,MATCH(L10,'00 - Lists'!$L$2:$L$11,0))),"") | R10: =IFERROR(IF(N10="","",N10*INDEX('00 - Lists'!$N$2:$N$11,MATCH(L10,'00 - Lists'!$L$2:$L$11,0))),"") | S10: =IF(O10="","",IF(O10>=50,"Yes","No")) | T10: =IF(Q10="","",IF(Q10>=100000,"Yes","No")) | BJ10: =IF(OR($BD10<>"",$BF10<>"",$BH10<>""),"Yes","No") -> No | BK10: =IFERROR(IF(BD10="","",BD10*INDEX('00 - Lists'!$M$2:$M$11,MATCH(L10,'00 - Lists'!$L$2:$L$11,0))/100000),"") | BL10: =IFERROR(IF(BE10="","",BE10*INDEX('00 - Lists'!$M$2:$M$11,MATCH(L10,'00 - Lists'!$L$2:$L$11,0))/100000),"") | BM10: =IFERROR(IF(BF10="","",BF10*INDEX('00 - Lists'!$M$2:$M$11,MATCH(L10,'00 - Lists'!$L$2:$L$11,0))/100000),"") | BN10: =IFERROR(IF(BG10="","",BG10*INDEX('00 - Lists'!$M$2:$M$11,MATCH(L10,'00 - Lists'!$L$2:$L$11,0))/100000),"") | BO10: =IFERROR(IF(BH10="","",BH10*INDEX('00 - Lists'!$M$2:$M$11,MATCH(L10,'00 - Lists'!$L$2:$L$11,0))/100000),"") | BP10: =IFERROR(IF(BI10="","",BI10*INDEX('00 - Lists'!$M$2:$M$11,MATCH(L10,'00 - Lists'!$L$2:$L$11,0))/100000),"") | BS10: =IF(O10="","",IF(O10>=20,"Yes","No")) | BT10: =IF(O10="","",IF(O10>=30,"Yes","No")) | BU10: =IF(O10="","",IF(O10>=75,"Yes","No")) | BV10: =IF(O10="","",IF(O10>=100,"Yes","No")) | BW10: =IF(O10="","",IF(O10>=150,"Yes","No")) | BX10: =IF(O10="","",IF(O10>=200,"Yes","No")) | BY10: =IF(Q10="","",IF(Q10>=150000,"Yes","No")) | BZ10: =IF(Q10="","",IF(Q10>=200000,"Yes","No")) | CA10: =IF(Q10="","",IF(Q10>=250000,"Yes","No")) | CB10: =IF(Q10="","",IF(Q10>=300000,"Yes","No")) | CD10: =IF(B10="","",IF(TODAY()-B10<=7,"🟢 0-7d",IF(TODAY()-B10<=30,"🟡 8-30d",IF(TODAY()-B10<=60,"🟠 31-60d","🔴 60d+")))) | CE10: =IF(G10="","",IF(G10<>"USA","N/A - Not USA Role",IF(J10="Yes",IF(OR(F10="Intern",F10="New Grad"),"🟡 Possible","🟢 Strong"),IF(J10="No","🔴 Difficult","⚪ Unknown"))))
A11: =IF($C11="","",ROW()-3) | O11: =IFERROR(IF(M11="","",M11*INDEX('00 - Lists'!$M$2:$M$11,MATCH(L11,'00 - Lists'!$L$2:$L$11,0))/100000),"") | P11: =IFERROR(IF(N11="","",N11*INDEX('00 - Lists'!$M$2:$M$11,MATCH(L11,'00 - Lists'!$L$2:$L$11,0))/100000),"") | Q11: =IFERROR(IF(M11="","",M11*INDEX('00 - Lists'!$N$2:$N$11,MATCH(L11,'00 - Lists'!$L$2:$L$11,0))),"") | R11: =IFERROR(IF(N11="","",N11*INDEX('00 - Lists'!$N$2:$N$11,MATCH(L11,'00 - Lists'!$L$2:$L$11,0))),"") | S11: =IF(O11="","",IF(O11>=50,"Yes","No")) | T11: =IF(Q11="","",IF(Q11>=100000,"Yes","No")) | BJ11: =IF(OR($BD11<>"",$BF11<>"",$BH11<>""),"Yes","No") -> No | BK11: =IFERROR(IF(BD11="","",BD11*INDEX('00 - Lists'!$M$2:$M$11,MATCH(L11,'00 - Lists'!$L$2:$L$11,0))/100000),"") | BL11: =IFERROR(IF(BE11="","",BE11*INDEX('00 - Lists'!$M$2:$M$11,MATCH(L11,'00 - Lists'!$L$2:$L$11,0))/100000),"") | BM11: =IFERROR(IF(BF11="","",BF11*INDEX('00 - Lists'!$M$2:$M$11,MATCH(L11,'00 - Lists'!$L$2:$L$11,0))/100000),"") | BN11: =IFERROR(IF(BG11="","",BG11*INDEX('00 - Lists'!$M$2:$M$11,MATCH(L11,'00 - Lists'!$L$2:$L$11,0))/100000),"") | BO11: =IFERROR(IF(BH11="","",BH11*INDEX('00 - Lists'!$M$2:$M$11,MATCH(L11,'00 - Lists'!$L$2:$L$11,0))/100000),"") | BP11: =IFERROR(IF(BI11="","",BI11*INDEX('00 - Lists'!$M$2:$M$11,MATCH(L11,'00 - Lists'!$L$2:$L$11,0))/100000),"") | BS11: =IF(O11="","",IF(O11>=20,"Yes","No")) | BT11: =IF(O11="","",IF(O11>=30,"Yes","No")) | BU11: =IF(O11="","",IF(O11>=75,"Yes","No")) | BV11: =IF(O11="","",IF(O11>=100,"Yes","No")) | BW11: =IF(O11="","",IF(O11>=150,"Yes","No")) | BX11: =IF(O11="","",IF(O11>=200,"Yes","No")) | BY11: =IF(Q11="","",IF(Q11>=150000,"Yes","No")) | BZ11: =IF(Q11="","",IF(Q11>=200000,"Yes","No")) | CA11: =IF(Q11="","",IF(Q11>=250000,"Yes","No")) | CB11: =IF(Q11="","",IF(Q11>=300000,"Yes","No")) | CD11: =IF(B11="","",IF(TODAY()-B11<=7,"🟢 0-7d",IF(TODAY()-B11<=30,"🟡 8-30d",IF(TODAY()-B11<=60,"🟠 31-60d","🔴 60d+")))) | CE11: =IF(G11="","",IF(G11<>"USA","N/A - Not USA Role",IF(J11="Yes",IF(OR(F11="Intern",F11="New Grad"),"🟡 Possible","🟢 Strong"),IF(J11="No","🔴 Difficult","⚪ Unknown"))))
A12: =IF($C12="","",ROW()-3) | O12: =IFERROR(IF(M12="","",M12*INDEX('00 - Lists'!$M$2:$M$11,MATCH(L12,'00 - Lists'!$L$2:$L$11,0))/100000),"") | P12: =IFERROR(IF(N12="","",N12*INDEX('00 - Lists'!$M$2:$M$11,MATCH(L12,'00 - Lists'!$L$2:$L$11,0))/100000),"") | Q12: =IFERROR(IF(M12="","",M12*INDEX('00 - Lists'!$N$2:$N$11,MATCH(L12,'00 - Lists'!$L$2:$L$11,0))),"") | R12: =IFERROR(IF(N12="","",N12*INDEX('00 - Lists'!$N$2:$N$11,MATCH(L12,'00 - Lists'!$L$2:$L$11,0))),"") | S12: =IF(O12="","",IF(O12>=50,"Yes","No")) | T12: =IF(Q12="","",IF(Q12>=100000,"Yes","No")) | BJ12: =IF(OR($BD12<>"",$BF12<>"",$BH12<>""),"Yes","No") -> No | BK12: =IFERROR(IF(BD12="","",BD12*INDEX('00 - Lists'!$M$2:$M$11,MATCH(L12,'00 - Lists'!$L$2:$L$11,0))/100000),"") | BL12: =IFERROR(IF(BE12="","",BE12*INDEX('00 - Lists'!$M$2:$M$11,MATCH(L12,'00 - Lists'!$L$2:$L$11,0))/100000),"") | BM12: =IFERROR(IF(BF12="","",BF12*INDEX('00 - Lists'!$M$2:$M$11,MATCH(L12,'00 - Lists'!$L$2:$L$11,0))/100000),"") | BN12: =IFERROR(IF(BG12="","",BG12*INDEX('00 - Lists'!$M$2:$M$11,MATCH(L12,'00 - Lists'!$L$2:$L$11,0))/100000),"") | BO12: =IFERROR(IF(BH12="","",BH12*INDEX('00 - Lists'!$M$2:$M$11,MATCH(L12,'00 - Lists'!$L$2:$L$11,0))/100000),"") | BP12: =IFERROR(IF(BI12="","",BI12*INDEX('00 - Lists'!$M$2:$M$11,MATCH(L12,'00 - Lists'!$L$2:$L$11,0))/100000),"") | BS12: =IF(O12="","",IF(O12>=20,"Yes","No")) | BT12: =IF(O12="","",IF(O12>=30,"Yes","No")) | BU12: =IF(O12="","",IF(O12>=75,"Yes","No")) | BV12: =IF(O12="","",IF(O12>=100,"Yes","No")) | BW12: =IF(O12="","",IF(O12>=150,"Yes","No")) | BX12: =IF(O12="","",IF(O12>=200,"Yes","No")) | BY12: =IF(Q12="","",IF(Q12>=150000,"Yes","No")) | BZ12: =IF(Q12="","",IF(Q12>=200000,"Yes","No")) | CA12: =IF(Q12="","",IF(Q12>=250000,"Yes","No")) | CB12: =IF(Q12="","",IF(Q12>=300000,"Yes","No")) | CD12: =IF(B12="","",IF(TODAY()-B12<=7,"🟢 0-7d",IF(TODAY()-B12<=30,"🟡 8-30d",IF(TODAY()-B12<=60,"🟠 31-60d","🔴 60d+")))) | CE12: =IF(G12="","",IF(G12<>"USA","N/A - Not USA Role",IF(J12="Yes",IF(OR(F12="Intern",F12="New Grad"),"🟡 Possible","🟢 Strong"),IF(J12="No","🔴 Difficult","⚪ Unknown"))))
A13: =IF($C13="","",ROW()-3) | O13: =IFERROR(IF(M13="","",M13*INDEX('00 - Lists'!$M$2:$M$11,MATCH(L13,'00 - Lists'!$L$2:$L$11,0))/100000),"") | P13: =IFERROR(IF(N13="","",N13*INDEX('00 - Lists'!$M$2:$M$11,MATCH(L13,'00 - Lists'!$L$2:$L$11,0))/100000),"") | Q13: =IFERROR(IF(M13="","",M13*INDEX('00 - Lists'!$N$2:$N$11,MATCH(L13,'00 - Lists'!$L$2:$L$11,0))),"") | R13: =IFERROR(IF(N13="","",N13*INDEX('00 - Lists'!$N$2:$N$11,MATCH(L13,'00 - Lists'!$L$2:$L$11,0))),"") | S13: =IF(O13="","",IF(O13>=50,"Yes","No")) | T13: =IF(Q13="","",IF(Q13>=100000,"Yes","No")) | BJ13: =IF(OR($BD13<>"",$BF13<>"",$BH13<>""),"Yes","No") -> No | BK13: =IFERROR(IF(BD13="","",BD13*INDEX('00 - Lists'!$M$2:$M$11,MATCH(L13,'00 - Lists'!$L$2:$L$11,0))/100000),"") | BL13: =IFERROR(IF(BE13="","",BE13*INDEX('00 - Lists'!$M$2:$M$11,MATCH(L13,'00 - Lists'!$L$2:$L$11,0))/100000),"") | BM13: =IFERROR(IF(BF13="","",BF13*INDEX('00 - Lists'!$M$2:$M$11,MATCH(L13,'00 - Lists'!$L$2:$L$11,0))/100000),"") | BN13: =IFERROR(IF(BG13="","",BG13*INDEX('00 - Lists'!$M$2:$M$11,MATCH(L13,'00 - Lists'!$L$2:$L$11,0))/100000),"") | BO13: =IFERROR(IF(BH13="","",BH13*INDEX('00 - Lists'!$M$2:$M$11,MATCH(L13,'00 - Lists'!$L$2:$L$11,0))/100000),"") | BP13: =IFERROR(IF(BI13="","",BI13*INDEX('00 - Lists'!$M$2:$M$11,MATCH(L13,'00 - Lists'!$L$2:$L$11,0))/100000),"") | BS13: =IF(O13="","",IF(O13>=20,"Yes","No")) | BT13: =IF(O13="","",IF(O13>=30,"Yes","No")) | BU13: =IF(O13="","",IF(O13>=75,"Yes","No")) | BV13: =IF(O13="","",IF(O13>=100,"Yes","No")) | BW13: =IF(O13="","",IF(O13>=150,"Yes","No")) | BX13: =IF(O13="","",IF(O13>=200,"Yes","No")) | BY13: =IF(Q13="","",IF(Q13>=150000,"Yes","No")) | BZ13: =IF(Q13="","",IF(Q13>=200000,"Yes","No")) | CA13: =IF(Q13="","",IF(Q13>=250000,"Yes","No")) | CB13: =IF(Q13="","",IF(Q13>=300000,"Yes","No")) | CD13: =IF(B13="","",IF(TODAY()-B13<=7,"🟢 0-7d",IF(TODAY()-B13<=30,"🟡 8-30d",IF(TODAY()-B13<=60,"🟠 31-60d","🔴 60d+")))) | CE13: =IF(G13="","",IF(G13<>"USA","N/A - Not USA Role",IF(J13="Yes",IF(OR(F13="Intern",F13="New Grad"),"🟡 Possible","🟢 Strong"),IF(J13="No","🔴 Difficult","⚪ Unknown"))))
A14: =IF($C14="","",ROW()-3) | O14: =IFERROR(IF(M14="","",M14*INDEX('00 - Lists'!$M$2:$M$11,MATCH(L14,'00 - Lists'!$L$2:$L$11,0))/100000),"") | P14: =IFERROR(IF(N14="","",N14*INDEX('00 - Lists'!$M$2:$M$11,MATCH(L14,'00 - Lists'!$L$2:$L$11,0))/100000),"") | Q14: =IFERROR(IF(M14="","",M14*INDEX('00 - Lists'!$N$2:$N$11,MATCH(L14,'00 - Lists'!$L$2:$L$11,0))),"") | R14: =IFERROR(IF(N14="","",N14*INDEX('00 - Lists'!$N$2:$N$11,MATCH(L14,'00 - Lists'!$L$2:$L$11,0))),"") | S14: =IF(O14="","",IF(O14>=50,"Yes","No")) | T14: =IF(Q14="","",IF(Q14>=100000,"Yes","No")) | BJ14: =IF(OR($BD14<>"",$BF14<>"",$BH14<>""),"Yes","No") -> No | BK14: =IFERROR(IF(BD14="","",BD14*INDEX('00 - Lists'!$M$2:$M$11,MATCH(L14,'00 - Lists'!$L$2:$L$11,0))/100000),"") | BL14: =IFERROR(IF(BE14="","",BE14*INDEX('00 - Lists'!$M$2:$M$11,MATCH(L14,'00 - Lists'!$L$2:$L$11,0))/100000),"") | BM14: =IFERROR(IF(BF14="","",BF14*INDEX('00 - Lists'!$M$2:$M$11,MATCH(L14,'00 - Lists'!$L$2:$L$11,0))/100000),"") | BN14: =IFERROR(IF(BG14="","",BG14*INDEX('00 - Lists'!$M$2:$M$11,MATCH(L14,'00 - Lists'!$L$2:$L$11,0))/100000),"") | BO14: =IFERROR(IF(BH14="","",BH14*INDEX('00 - Lists'!$M$2:$M$11,MATCH(L14,'00 - Lists'!$L$2:$L$11,0))/100000),"") | BP14: =IFERROR(IF(BI14="","",BI14*INDEX('00 - Lists'!$M$2:$M$11,MATCH(L14,'00 - Lists'!$L$2:$L$11,0))/100000),"") | BS14: =IF(O14="","",IF(O14>=20,"Yes","No")) | BT14: =IF(O14="","",IF(O14>=30,"Yes","No")) | BU14: =IF(O14="","",IF(O14>=75,"Yes","No")) | BV14: =IF(O14="","",IF(O14>=100,"Yes","No")) | BW14: =IF(O14="","",IF(O14>=150,"Yes","No")) | BX14: =IF(O14="","",IF(O14>=200,"Yes","No")) | BY14: =IF(Q14="","",IF(Q14>=150000,"Yes","No")) | BZ14: =IF(Q14="","",IF(Q14>=200000,"Yes","No")) | CA14: =IF(Q14="","",IF(Q14>=250000,"Yes","No")) | CB14: =IF(Q14="","",IF(Q14>=300000,"Yes","No")) | CD14: =IF(B14="","",IF(TODAY()-B14<=7,"🟢 0-7d",IF(TODAY()-B14<=30,"🟡 8-30d",IF(TODAY()-B14<=60,"🟠 31-60d","🔴 60d+")))) | CE14: =IF(G14="","",IF(G14<>"USA","N/A - Not USA Role",IF(J14="Yes",IF(OR(F14="Intern",F14="New Grad"),"🟡 Possible","🟢 Strong"),IF(J14="No","🔴 Difficult","⚪ Unknown"))))
A15: =IF($C15="","",ROW()-3) | O15: =IFERROR(IF(M15="","",M15*INDEX('00 - Lists'!$M$2:$M$11,MATCH(L15,'00 - Lists'!$L$2:$L$11,0))/100000),"") | P15: =IFERROR(IF(N15="","",N15*INDEX('00 - Lists'!$M$2:$M$11,MATCH(L15,'00 - Lists'!$L$2:$L$11,0))/100000),"") | Q15: =IFERROR(IF(M15="","",M15*INDEX('00 - Lists'!$N$2:$N$11,MATCH(L15,'00 - Lists'!$L$2:$L$11,0))),"") | R15: =IFERROR(IF(N15="","",N15*INDEX('00 - Lists'!$N$2:$N$11,MATCH(L15,'00 - Lists'!$L$2:$L$11,0))),"") | S15: =IF(O15="","",IF(O15>=50,"Yes","No")) | T15: =IF(Q15="","",IF(Q15>=100000,"Yes","No")) | BJ15: =IF(OR($BD15<>"",$BF15<>"",$BH15<>""),"Yes","No") -> No | BK15: =IFERROR(IF(BD15="","",BD15*INDEX('00 - Lists'!$M$2:$M$11,MATCH(L15,'00 - Lists'!$L$2:$L$11,0))/100000),"") | BL15: =IFERROR(IF(BE15="","",BE15*INDEX('00 - Lists'!$M$2:$M$11,MATCH(L15,'00 - Lists'!$L$2:$L$11,0))/100000),"") | BM15: =IFERROR(IF(BF15="","",BF15*INDEX('00 - Lists'!$M$2:$M$11,MATCH(L15,'00 - Lists'!$L$2:$L$11,0))/100000),"") | BN15: =IFERROR(IF(BG15="","",BG15*INDEX('00 - Lists'!$M$2:$M$11,MATCH(L15,'00 - Lists'!$L$2:$L$11,0))/100000),"") | BO15: =IFERROR(IF(BH15="","",BH15*INDEX('00 - Lists'!$M$2:$M$11,MATCH(L15,'00 - Lists'!$L$2:$L$11,0))/100000),"") | BP15: =IFERROR(IF(BI15="","",BI15*INDEX('00 - Lists'!$M$2:$M$11,MATCH(L15,'00 - Lists'!$L$2:$L$11,0))/100000),"") | BS15: =IF(O15="","",IF(O15>=20,"Yes","No")) | BT15: =IF(O15="","",IF(O15>=30,"Yes","No")) | BU15: =IF(O15="","",IF(O15>=75,"Yes","No")) | BV15: =IF(O15="","",IF(O15>=100,"Yes","No")) | BW15: =IF(O15="","",IF(O15>=150,"Yes","No")) | BX15: =IF(O15="","",IF(O15>=200,"Yes","No")) | BY15: =IF(Q15="","",IF(Q15>=150000,"Yes","No")) | BZ15: =IF(Q15="","",IF(Q15>=200000,"Yes","No")) | CA15: =IF(Q15="","",IF(Q15>=250000,"Yes","No")) | CB15: =IF(Q15="","",IF(Q15>=300000,"Yes","No")) | CD15: =IF(B15="","",IF(TODAY()-B15<=7,"🟢 0-7d",IF(TODAY()-B15<=30,"🟡 8-30d",IF(TODAY()-B15<=60,"🟠 31-60d","🔴 60d+")))) | CE15: =IF(G15="","",IF(G15<>"USA","N/A - Not USA Role",IF(J15="Yes",IF(OR(F15="Intern",F15="New Grad"),"🟡 Possible","🟢 Strong"),IF(J15="No","🔴 Difficult","⚪ Unknown"))))
A16: =IF($C16="","",ROW()-3) | O16: =IFERROR(IF(M16="","",M16*INDEX('00 - Lists'!$M$2:$M$11,MATCH(L16,'00 - Lists'!$L$2:$L$11,0))/100000),"") | P16: =IFERROR(IF(N16="","",N16*INDEX('00 - Lists'!$M$2:$M$11,MATCH(L16,'00 - Lists'!$L$2:$L$11,0))/100000),"") | Q16: =IFERROR(IF(M16="","",M16*INDEX('00 - Lists'!$N$2:$N$11,MATCH(L16,'00 - Lists'!$L$2:$L$11,0))),"") | R16: =IFERROR(IF(N16="","",N16*INDEX('00 - Lists'!$N$2:$N$11,MATCH(L16,'00 - Lists'!$L$2:$L$11,0))),"") | S16: =IF(O16="","",IF(O16>=50,"Yes","No")) | T16: =IF(Q16="","",IF(Q16>=100000,"Yes","No")) | BJ16: =IF(OR($BD16<>"",$BF16<>"",$BH16<>""),"Yes","No") -> No | BK16: =IFERROR(IF(BD16="","",BD16*INDEX('00 - Lists'!$M$2:$M$11,MATCH(L16,'00 - Lists'!$L$2:$L$11,0))/100000),"") | BL16: =IFERROR(IF(BE16="","",BE16*INDEX('00 - Lists'!$M$2:$M$11,MATCH(L16,'00 - Lists'!$L$2:$L$11,0))/100000),"") | BM16: =IFERROR(IF(BF16="","",BF16*INDEX('00 - Lists'!$M$2:$M$11,MATCH(L16,'00 - Lists'!$L$2:$L$11,0))/100000),"") | BN16: =IFERROR(IF(BG16="","",BG16*INDEX('00 - Lists'!$M$2:$M$11,MATCH(L16,'00 - Lists'!$L$2:$L$11,0))/100000),"") | BO16: =IFERROR(IF(BH16="","",BH16*INDEX('00 - Lists'!$M$2:$M$11,MATCH(L16,'00 - Lists'!$L$2:$L$11,0))/100000),"") | BP16: =IFERROR(IF(BI16="","",BI16*INDEX('00 - Lists'!$M$2:$M$11,MATCH(L16,'00 - Lists'!$L$2:$L$11,0))/100000),"") | BS16: =IF(O16="","",IF(O16>=20,"Yes","No")) | BT16: =IF(O16="","",IF(O16>=30,"Yes","No")) | BU16: =IF(O16="","",IF(O16>=75,"Yes","No")) | BV16: =IF(O16="","",IF(O16>=100,"Yes","No")) | BW16: =IF(O16="","",IF(O16>=150,"Yes","No")) | BX16: =IF(O16="","",IF(O16>=200,"Yes","No")) | BY16: =IF(Q16="","",IF(Q16>=150000,"Yes","No")) | BZ16: =IF(Q16="","",IF(Q16>=200000,"Yes","No")) | CA16: =IF(Q16="","",IF(Q16>=250000,"Yes","No")) | CB16: =IF(Q16="","",IF(Q16>=300000,"Yes","No")) | CD16: =IF(B16="","",IF(TODAY()-B16<=7,"🟢 0-7d",IF(TODAY()-B16<=30,"🟡 8-30d",IF(TODAY()-B16<=60,"🟠 31-60d","🔴 60d+")))) | CE16: =IF(G16="","",IF(G16<>"USA","N/A - Not USA Role",IF(J16="Yes",IF(OR(F16="Intern",F16="New Grad"),"🟡 Possible","🟢 Strong"),IF(J16="No","🔴 Difficult","⚪ Unknown"))))
... A1000: =IF($C1000="","",ROW()-3) | O1000: =IFERROR(IF(M1000="","",M1000*INDEX('00 - Lists'!$M$2:$M$11,MATCH(L1000,'00 - Lists'!$L$2:$L$11,0))/100000),"") | P1000: =IFERROR(IF(N1000="","",N1000*INDEX('00 - Lists'!$M$2:$M$11,MATCH(L1000,'00 - Lists'!$L$2:$L$11,0))/100000),"") | Q1000: =IFERROR(IF(M1000="","",M1000*INDEX('00 - Lists'!$N$2:$N$11,MATCH(L1000,'00 - Lists'!$L$2:$L$11,0))),"") | R1000: =IFERROR(IF(N1000="","",N1000*INDEX('00 - Lists'!$N$2:$N$11,MATCH(L1000,'00 - Lists'!$L$2:$L$11,0))),"") | S1000: =IF(O1000="","",IF(O1000>=50,"Yes","No")) | T1000: =IF(Q1000="","",IF(Q1000>=100000,"Yes","No")) | BJ1000: =IF(OR($BD1000<>"",$BF1000<>"",$BH1000<>""),"Yes","No") -> No | BK1000: =IFERROR(IF(BD1000="","",BD1000*INDEX('00 - Lists'!$M$2:$M$11,MATCH(L1000,'00 - Lists'!$L$2:$L$11,0))/100000),"") | BL1000: =IFERROR(IF(BE1000="","",BE1000*INDEX('00 - Lists'!$M$2:$M$11,MATCH(L1000,'00 - Lists'!$L$2:$L$11,0))/100000),"") | BM1000: =IFERROR(IF(BF1000="","",BF1000*INDEX('00 - Lists'!$M$2:$M$11,MATCH(L1000,'00 - Lists'!$L$2:$L$11,0))/100000),"") | BN1000: =IFERROR(IF(BG1000="","",BG1000*INDEX('00 - Lists'!$M$2:$M$11,MATCH(L1000,'00 - Lists'!$L$2:$L$11,0))/100000),"") | BO1000: =IFERROR(IF(BH1000="","",BH1000*INDEX('00 - Lists'!$M$2:$M$11,MATCH(L1000,'00 - Lists'!$L$2:$L$11,0))/100000),"") | BP1000: =IFERROR(IF(BI1000="","",BI1000*INDEX('00 - Lists'!$M$2:$M$11,MATCH(L1000,'00 - Lists'!$L$2:$L$11,0))/100000),"") | BS1000: =IF(O1000="","",IF(O1000>=20,"Yes","No")) | BT1000: =IF(O1000="","",IF(O1000>=30,"Yes","No")) | BU1000: =IF(O1000="","",IF(O1000>=75,"Yes","No")) | BV1000: =IF(O1000="","",IF(O1000>=100,"Yes","No")) | BW1000: =IF(O1000="","",IF(O1000>=150,"Yes","No")) | BX1000: =IF(O1000="","",IF(O1000>=200,"Yes","No")) | BY1000: =IF(Q1000="","",IF(Q1000>=150000,"Yes","No")) | BZ1000: =IF(Q1000="","",IF(Q1000>=200000,"Yes","No")) | CA1000: =IF(Q1000="","",IF(Q1000>=250000,"Yes","No")) | CB1000: =IF(Q1000="","",IF(Q1000>=300000,"Yes","No")) | CD1000: =IF(B1000="","",IF(TODAY()-B1000<=7,"🟢 0-7d",IF(TODAY()-B1000<=30,"🟡 8-30d",IF(TODAY()-B1000<=60,"🟠 31-60d","🔴 60d+")))) | CE1000: =IF(G1000="","",IF(G1000<>"USA","N/A - Not USA Role",IF(J1000="Yes",IF(OR(F1000="Intern",F1000="New Grad"),"🟡 Possible","🟢 Strong"),IF(J1000="No","🔴 Difficult","⚪ Unknown"))))

Sheet 02 - Dashboard
A1: 02 · DASHBOARD — the market picture, updated automatically as you add jobs
A3: Total Opportunities Tracked: | B3: =COUNTIFS('01 - Job Database'!$C$3:$C$1000,"<>",'01 - Job Database'!$W$3:$W$1000,"<>Yes") -> 1
A5: OVERVIEW
A6: ='02 - Dashboard'!$B$3 -> 1 | C6: =COUNTIFS('01 - Job Database'!$C$3:$C$1000,"<>",'01 - Job Database'!$W$3:$W$1000,"<>Yes",'01 - Job Database'!$G$3:$G$1000,"India") -> 0 | E6: =IFERROR('02 - Dashboard'!$B$3-COUNTIFS('01 - Job Database'!$C$3:$C$1000,"<>",'01 - Job Database'!$W$3:$W$1000,"<>Yes",'01 - Job Database'!$G$3:$G$1000,"India"),0) -> 1 | G6: =COUNTIF('05 - Country Intelligence'!$B$4:$B$21,">0") -> 1
A8: Total Opportunities | C8: India Opportunities | E8: International Opportunities | G8: Countries Represented
A10: =COUNTIFS('01 - Job Database'!$C$3:$C$1000,"<>",'01 - Job Database'!$W$3:$W$1000,"<>Yes",'01 - Job Database'!$S$3:$S$1000,"Yes") -> 1 | C10: =COUNTIFS('01 - Job Database'!$C$3:$C$1000,"<>",'01 - Job Database'!$W$3:$W$1000,"<>Yes",'01 - Job Database'!$T$3:$T$1000,"Yes") -> 1 | E10: =COUNTIFS('01 - Job Database'!$C$3:$C$1000,"<>",'01 - Job Database'!$W$3:$W$1000,"<>Yes",'01 - Job Database'!$Q$3:$Q$1000,">=150000") -> 0 | G10: =(COUNTIFS('01 - Job Database'!$C$3:$C$1000,"<>",'01 - Job Database'!$W$3:$W$1000,"<>Yes",'01 - Job Database'!$F$3:$F$1000,"Intern")+COUNTIFS('01 - Job Database'!$C$3:$C$1000,"<>",'01 - Job Database'!$W$3:$W$1000,"<>Yes",'01 - Job Database'!$F$3:$F$1000,"New Grad")) -> 0
A12: INR 50L+ Opportunities | C12: USD 100k+ Opportunities | E12: USD 150k+ Opportunities | G12: New Grad Opportunities
A14: =IFERROR(COUNTIFS('01 - Job Database'!$C$3:$C$1000,"<>",'01 - Job Database'!$W$3:$W$1000,"<>Yes",'01 - Job Database'!$J$3:$J$1000,"Yes")/'02 - Dashboard'!$B$3,0) -> 0 | C14: =COUNTIFS('01 - Job Database'!$C$3:$C$1000,"<>",'01 - Job Database'!$W$3:$W$1000,"<>Yes",'01 - Job Database'!$J$3:$J$1000,"Yes") -> 0 | E14: =IFERROR(COUNTIFS('01 - Job Database'!$C$3:$C$1000,"<>",'01 - Job Database'!$W$3:$W$1000,"<>Yes",'01 - Job Database'!$K$3:$K$1000,"Yes")/'02 - Dashboard'!$B$3,0) -> 0 | G14: =IFERROR((COUNTIFS('01 - Job Database'!$C$3:$C$1000,"<>",'01 - Job Database'!$W$3:$W$1000,"<>Yes",'01 - Job Database'!$F$3:$F$1000,"Intern")+COUNTIFS('01 - Job Database'!$C$3:$C$1000,"<>",'01 - Job Database'!$W$3:$W$1000,"<>Yes",'01 - Job Database'!$F$3:$F$1000,"New Grad"))/'02 - Dashboard'!$B$3,0) -> 0
A16: Visa Sponsorship % | C16: H-1B / Visa Support Count | E16: Relocation Support % | G16: New Grad Share
A18: TOP 5 COMPANIES | E18: TOP 5 ROLES
A19: # | B19: Company | C19: Jobs | E19: # | F19: Role | G19: Jobs
A20: 1 | B20: =IFERROR(INDEX('06 - Company Intelligence'!$A$4:$A$49,MATCH(LARGE('06 - Company Intelligence'!$H$4:$H$49,1),'06 - Company Intelligence'!$H$4:$H$49,0)),"—") -> Amazon | C20: =IFERROR(INDEX('06 - Company Intelligence'!$B$4:$B$49,MATCH(LARGE('06 - Company Intelligence'!$H$4:$H$49,1),'06 - Company Intelligence'!$H$4:$H$49,0)),"") -> 1 | E20: 1 | F20: =IFERROR(INDEX('04 - Role Intelligence'!$A$4:$A$19,MATCH(LARGE('04 - Role Intelligence'!$H$4:$H$19,1),'04 - Role Intelligence'!$H$4:$H$19,0)),"—") -> SWE / General | G20: =IFERROR(INDEX('04 - Role Intelligence'!$B$4:$B$19,MATCH(LARGE('04 - Role Intelligence'!$H$4:$H$19,1),'04 - Role Intelligence'!$H$4:$H$19,0)),"") -> 0
A21: 2 | B21: =IFERROR(INDEX('06 - Company Intelligence'!$A$4:$A$49,MATCH(LARGE('06 - Company Intelligence'!$H$4:$H$49,2),'06 - Company Intelligence'!$H$4:$H$49,0)),"—") -> Google | C21: =IFERROR(INDEX('06 - Company Intelligence'!$B$4:$B$49,MATCH(LARGE('06 - Company Intelligence'!$H$4:$H$49,2),'06 - Company Intelligence'!$H$4:$H$49,0)),"") -> 0 | E21: 2 | F21: =IFERROR(INDEX('04 - Role Intelligence'!$A$4:$A$19,MATCH(LARGE('04 - Role Intelligence'!$H$4:$H$19,2),'04 - Role Intelligence'!$H$4:$H$19,0)),"—") -> Backend Engineer | G21: =IFERROR(INDEX('04 - Role Intelligence'!$B$4:$B$19,MATCH(LARGE('04 - Role Intelligence'!$H$4:$H$19,2),'04 - Role Intelligence'!$H$4:$H$19,0)),"") -> 0
A22: 3 | B22: =IFERROR(INDEX('06 - Company Intelligence'!$A$4:$A$49,MATCH(LARGE('06 - Company Intelligence'!$H$4:$H$49,3),'06 - Company Intelligence'!$H$4:$H$49,0)),"—") -> Meta | C22: =IFERROR(INDEX('06 - Company Intelligence'!$B$4:$B$49,MATCH(LARGE('06 - Company Intelligence'!$H$4:$H$49,3),'06 - Company Intelligence'!$H$4:$H$49,0)),"") -> 0 | E22: 3 | F22: =IFERROR(INDEX('04 - Role Intelligence'!$A$4:$A$19,MATCH(LARGE('04 - Role Intelligence'!$H$4:$H$19,3),'04 - Role Intelligence'!$H$4:$H$19,0)),"—") -> Frontend Engineer | G22: =IFERROR(INDEX('04 - Role Intelligence'!$B$4:$B$19,MATCH(LARGE('04 - Role Intelligence'!$H$4:$H$19,3),'04 - Role Intelligence'!$H$4:$H$19,0)),"") -> 0
A23: 4 | B23: =IFERROR(INDEX('06 - Company Intelligence'!$A$4:$A$49,MATCH(LARGE('06 - Company Intelligence'!$H$4:$H$49,4),'06 - Company Intelligence'!$H$4:$H$49,0)),"—") -> Apple | C23: =IFERROR(INDEX('06 - Company Intelligence'!$B$4:$B$49,MATCH(LARGE('06 - Company Intelligence'!$H$4:$H$49,4),'06 - Company Intelligence'!$H$4:$H$49,0)),"") -> 0 | E23: 4 | F23: =IFERROR(INDEX('04 - Role Intelligence'!$A$4:$A$19,MATCH(LARGE('04 - Role Intelligence'!$H$4:$H$19,4),'04 - Role Intelligence'!$H$4:$H$19,0)),"—") -> Cloud Engineer | G23: =IFERROR(INDEX('04 - Role Intelligence'!$B$4:$B$19,MATCH(LARGE('04 - Role Intelligence'!$H$4:$H$19,4),'04 - Role Intelligence'!$H$4:$H$19,0)),"") -> 0
A24: 5 | B24: =IFERROR(INDEX('06 - Company Intelligence'!$A$4:$A$49,MATCH(LARGE('06 - Company Intelligence'!$H$4:$H$49,5),'06 - Company Intelligence'!$H$4:$H$49,0)),"—") -> Netflix | C24: =IFERROR(INDEX('06 - Company Intelligence'!$B$4:$B$49,MATCH(LARGE('06 - Company Intelligence'!$H$4:$H$49,5),'06 - Company Intelligence'!$H$4:$H$49,0)),"") -> 0 | E24: 5 | F24: =IFERROR(INDEX('04 - Role Intelligence'!$A$4:$A$19,MATCH(LARGE('04 - Role Intelligence'!$H$4:$H$19,5),'04 - Role Intelligence'!$H$4:$H$19,0)),"—") -> DevOps Engineer | G24: =IFERROR(INDEX('04 - Role Intelligence'!$B$4:$B$19,MATCH(LARGE('04 - Role Intelligence'!$H$4:$H$19,5),'04 - Role Intelligence'!$H$4:$H$19,0)),"") -> 0
A26: TOP 5 TECHNOLOGIES / SKILLS | E26: TOP 5 COUNTRIES
A27: # | B27: Skill | C27: Jobs | E27: # | F27: Country | G27: Jobs
A28: 1 | B28: =IFERROR(INDEX('03 - Skill Intelligence'!$B$6:$B$48,MATCH(LARGE('03 - Skill Intelligence'!$E$6:$E$48,1),'03 - Skill Intelligence'!$E$6:$E$48,0)),"—") -> C++ | C28: =IFERROR(INDEX('03 - Skill Intelligence'!$C$6:$C$37,MATCH(LARGE('03 - Skill Intelligence'!$E$6:$E$37,1),'03 - Skill Intelligence'!$E$6:$E$37,0)),"") -> 1 | E28: 1 | F28: =IFERROR(INDEX('05 - Country Intelligence'!$A$4:$A$21,MATCH(LARGE('05 - Country Intelligence'!$G$4:$G$21,1),'05 - Country Intelligence'!$G$4:$G$21,0)),"—") -> USA | G28: =IFERROR(INDEX('05 - Country Intelligence'!$B$4:$B$21,MATCH(LARGE('05 - Country Intelligence'!$G$4:$G$21,1),'05 - Country Intelligence'!$G$4:$G$21,0)),"") -> 1
A29: 2 | B29: =IFERROR(INDEX('03 - Skill Intelligence'!$B$6:$B$48,MATCH(LARGE('03 - Skill Intelligence'!$E$6:$E$48,2),'03 - Skill Intelligence'!$E$6:$E$48,0)),"—") -> Java | C29: =IFERROR(INDEX('03 - Skill Intelligence'!$C$6:$C$37,MATCH(LARGE('03 - Skill Intelligence'!$E$6:$E$37,2),'03 - Skill Intelligence'!$E$6:$E$37,0)),"") -> 1 | E29: 2 | F29: =IFERROR(INDEX('05 - Country Intelligence'!$A$4:$A$21,MATCH(LARGE('05 - Country Intelligence'!$G$4:$G$21,2),'05 - Country Intelligence'!$G$4:$G$21,0)),"—") -> India | G29: =IFERROR(INDEX('05 - Country Intelligence'!$B$4:$B$21,MATCH(LARGE('05 - Country Intelligence'!$G$4:$G$21,2),'05 - Country Intelligence'!$G$4:$G$21,0)),"") -> 0
A30: 3 | B30: =IFERROR(INDEX('03 - Skill Intelligence'!$B$6:$B$48,MATCH(LARGE('03 - Skill Intelligence'!$E$6:$E$48,3),'03 - Skill Intelligence'!$E$6:$E$48,0)),"—") -> Multithreading & Concurrency | C30: =IFERROR(INDEX('03 - Skill Intelligence'!$C$6:$C$37,MATCH(LARGE('03 - Skill Intelligence'!$E$6:$E$37,3),'03 - Skill Intelligence'!$E$6:$E$37,0)),"") -> 1 | E30: 3 | F30: =IFERROR(INDEX('05 - Country Intelligence'!$A$4:$A$21,MATCH(LARGE('05 - Country Intelligence'!$G$4:$G$21,3),'05 - Country Intelligence'!$G$4:$G$21,0)),"—") -> UK | G30: =IFERROR(INDEX('05 - Country Intelligence'!$B$4:$B$21,MATCH(LARGE('05 - Country Intelligence'!$G$4:$G$21,3),'05 - Country Intelligence'!$G$4:$G$21,0)),"") -> 0
A31: 4 | B31: =IFERROR(INDEX('03 - Skill Intelligence'!$B$6:$B$48,MATCH(LARGE('03 - Skill Intelligence'!$E$6:$E$48,4),'03 - Skill Intelligence'!$E$6:$E$48,0)),"—") -> Distributed Systems | C31: =IFERROR(INDEX('03 - Skill Intelligence'!$C$6:$C$37,MATCH(LARGE('03 - Skill Intelligence'!$E$6:$E$37,4),'03 - Skill Intelligence'!$E$6:$E$37,0)),"") -> 1 | E31: 4 | F31: =IFERROR(INDEX('05 - Country Intelligence'!$A$4:$A$21,MATCH(LARGE('05 - Country Intelligence'!$G$4:$G$21,4),'05 - Country Intelligence'!$G$4:$G$21,0)),"—") -> Germany | G31: =IFERROR(INDEX('05 - Country Intelligence'!$B$4:$B$21,MATCH(LARGE('05 - Country Intelligence'!$G$4:$G$21,4),'05 - Country Intelligence'!$G$4:$G$21,0)),"") -> 0
A32: 5 | B32: =IFERROR(INDEX('03 - Skill Intelligence'!$B$6:$B$48,MATCH(LARGE('03 - Skill Intelligence'!$E$6:$E$48,5),'03 - Skill Intelligence'!$E$6:$E$48,0)),"—") -> AWS | C32: =IFERROR(INDEX('03 - Skill Intelligence'!$C$6:$C$37,MATCH(LARGE('03 - Skill Intelligence'!$E$6:$E$37,5),'03 - Skill Intelligence'!$E$6:$E$37,0)),"") -> 1 | E32: 5 | F32: =IFERROR(INDEX('05 - Country Intelligence'!$A$4:$A$21,MATCH(LARGE('05 - Country Intelligence'!$G$4:$G$21,5),'05 - Country Intelligence'!$G$4:$G$21,0)),"—") -> Netherlands | G32: =IFERROR(INDEX('05 - Country Intelligence'!$B$4:$B$21,MATCH(LARGE('05 - Country Intelligence'!$G$4:$G$21,5),'05 - Country Intelligence'!$G$4:$G$21,0)),"") -> 0
A34: Tip: these tables auto-update the moment you log a matching job in 01 - Job Database. All zero right now because no real jobs are logged yet.
A36: FILTERED VIEW — pick any combination below (leave blank to include all jobs)
A37: Role | B37: Level | C37: Country | D37: Min Total Comp (INR L) | E37: Visa Sponsorship | F37: Relocation Support
A40: Matching Jobs | C40: Avg Total Comp Min (INR L) | E40: Visa Sponsorship % (of matches) | G40: India Share (of matches)
A41: =SUMPRODUCT(('01 - Job Database'!$C$3:$C$1000<>"")*('01 - Job Database'!$W$3:$W$1000<>"Yes")*(('01 - Job Database'!$E$3:$E$1000=$A$38)+($A$38=""))*(('01 - Job Database'!$F$3:$F$1000=$B$38)+($B$38=""))*(('01 - Job Database'!$G$3:$G$1000=$C$38)+($C$38=""))*(('01 - Job Database'!$O$3:$O$1000>=$D$38)+($D$38=""))*(('01 - Job Database'!$J$3:$J$1000=$E$38)+($E$38=""))*(('01 - Job Database'!$K$3:$K$1000=$F$38)+($F$38=""))) -> 2 | C41: =IFERROR(SUMPRODUCT(N('01 - Job Database'!$O$3:$O$1000)*(('01 - Job Database'!$C$3:$C$1000<>"")*('01 - Job Database'!$W$3:$W$1000<>"Yes")*(('01 - Job Database'!$E$3:$E$1000=$A$38)+($A$38=""))*(('01 - Job Database'!$F$3:$F$1000=$B$38)+($B$38=""))*(('01 - Job Database'!$G$3:$G$1000=$C$38)+($C$38=""))*(('01 - Job Database'!$O$3:$O$1000>=$D$38)+($D$38=""))*(('01 - Job Database'!$J$3:$J$1000=$E$38)+($E$38=""))*(('01 - Job Database'!$K$3:$K$1000=$F$38)+($F$38=""))))/SUMPRODUCT((('01 - Job Database'!$C$3:$C$1000<>"")*('01 - Job Database'!$W$3:$W$1000<>"Yes")*(('01 - Job Database'!$E$3:$E$1000=$A$38)+($A$38=""))*(('01 - Job Database'!$F$3:$F$1000=$B$38)+($B$38=""))*(('01 - Job Database'!$G$3:$G$1000=$C$38)+($C$38=""))*(('01 - Job Database'!$O$3:$O$1000>=$D$38)+($D$38=""))*(('01 - Job Database'!$J$3:$J$1000=$E$38)+($E$38=""))*(('01 - Job Database'!$K$3:$K$1000=$F$38)+($F$38="")))*('01 - Job Database'!$O$3:$O$1000<>"")),"") -> 125.019 | E41: =IFERROR(SUMPRODUCT((('01 - Job Database'!$C$3:$C$1000<>"")*('01 - Job Database'!$W$3:$W$1000<>"Yes")*(('01 - Job Database'!$E$3:$E$1000=$A$38)+($A$38=""))*(('01 - Job Database'!$F$3:$F$1000=$B$38)+($B$38=""))*(('01 - Job Database'!$G$3:$G$1000=$C$38)+($C$38=""))*(('01 - Job Database'!$O$3:$O$1000>=$D$38)+($D$38=""))*(('01 - Job Database'!$J$3:$J$1000=$E$38)+($E$38=""))*(('01 - Job Database'!$K$3:$K$1000=$F$38)+($F$38="")))*('01 - Job Database'!$J$3:$J$1000="Yes"))/A41,"") -> 0 | G41: =IFERROR(SUMPRODUCT((('01 - Job Database'!$C$3:$C$1000<>"")*('01 - Job Database'!$W$3:$W$1000<>"Yes")*(('01 - Job Database'!$E$3:$E$1000=$A$38)+($A$38=""))*(('01 - Job Database'!$F$3:$F$1000=$B$38)+($B$38=""))*(('01 - Job Database'!$G$3:$G$1000=$C$38)+($C$38=""))*(('01 - Job Database'!$O$3:$O$1000>=$D$38)+($D$38=""))*(('01 - Job Database'!$J$3:$J$1000=$E$38)+($E$38=""))*(('01 - Job Database'!$K$3:$K$1000=$F$38)+($F$38="")))*('01 - Job Database'!$G$3:$G$1000="India"))/A41,"") -> 0
A43: Note: 'Min Total Comp' filters on Total Comp Min (INR Lakhs). Visa/Relocation dropdowns match Yes/No/Unknown exactly.

Sheet 03 - Skill Intelligence
A1: 03 · SKILL INTELLIGENCE — which skills appear most often across every job you've logged
A3: Total Active Jobs Logged: | B3: =COUNTIFS('01 - Job Database'!$C$3:$C$1000,"<>",'01 - Job Database'!$W$3:$W$1000,"<>Yes") -> 1
A5: Category | B5: Skill | C5: Jobs Requiring | D5: % of Active Jobs | E5: RankKey (helper)
A6: Languages | B6: C++ | C6: =COUNTIFS('01 - Job Database'!$C$3:$C$1000,"<>",'01 - Job Database'!$W$3:$W$1000,"<>Yes",'01 - Job Database'!$X$3:$X$1000,"Yes") -> 1 | D6: =IFERROR(C6/'03 - Skill Intelligence'!$B$3,0) -> 1 | E6: =C6-ROW()*0.0001 -> 0.9994
A7: Languages | B7: Python | C7: =COUNTIFS('01 - Job Database'!$C$3:$C$1000,"<>",'01 - Job Database'!$W$3:$W$1000,"<>Yes",'01 - Job Database'!$Y$3:$Y$1000,"Yes") -> 0 | D7: =IFERROR(C7/'03 - Skill Intelligence'!$B$3,0) -> 0 | E7: =C7-ROW()*0.0001 -> -0.0007
A8: Languages | B8: Java | C8: =COUNTIFS('01 - Job Database'!$C$3:$C$1000,"<>",'01 - Job Database'!$W$3:$W$1000,"<>Yes",'01 - Job Database'!$Z$3:$Z$1000,"Yes") -> 1 | D8: =IFERROR(C8/'03 - Skill Intelligence'!$B$3,0) -> 1 | E8: =C8-ROW()*0.0001 -> 0.9992
A9: Languages | B9: Go | C9: =COUNTIFS('01 - Job Database'!$C$3:$C$1000,"<>",'01 - Job Database'!$W$3:$W$1000,"<>Yes",'01 - Job Database'!$AA$3:$AA$1000,"Yes") -> 0 | D9: =IFERROR(C9/'03 - Skill Intelligence'!$B$3,0) -> 0 | E9: =C9-ROW()*0.0001 -> -0.0009
A10: Languages | B10: Rust | C10: =COUNTIFS('01 - Job Database'!$C$3:$C$1000,"<>",'01 - Job Database'!$W$3:$W$1000,"<>Yes",'01 - Job Database'!$AB$3:$AB$1000,"Yes") -> 0 | D10: =IFERROR(C10/'03 - Skill Intelligence'!$B$3,0) -> 0 | E10: =C10-ROW()*0.0001 -> -0.001
A11: Languages | B11: JavaScript/TypeScript | C11: =COUNTIFS('01 - Job Database'!$C$3:$C$1000,"<>",'01 - Job Database'!$W$3:$W$1000,"<>Yes",'01 - Job Database'!$AC$3:$AC$1000,"Yes") -> 0 | D11: =IFERROR(C11/'03 - Skill Intelligence'!$B$3,0) -> 0 | E11: =C11-ROW()*0.0001 -> -0.0011
A12: Languages | B12: C | C12: =COUNTIFS('01 - Job Database'!$C$3:$C$1000,"<>",'01 - Job Database'!$W$3:$W$1000,"<>Yes",'01 - Job Database'!$AD$3:$AD$1000,"Yes") -> 0 | D12: =IFERROR(C12/'03 - Skill Intelligence'!$B$3,0) -> 0 | E12: =C12-ROW()*0.0001 -> -0.0012
A13: Languages | B13: SQL | C13: =COUNTIFS('01 - Job Database'!$C$3:$C$1000,"<>",'01 - Job Database'!$W$3:$W$1000,"<>Yes",'01 - Job Database'!$AE$3:$AE$1000,"Yes") -> 0 | D13: =IFERROR(C13/'03 - Skill Intelligence'!$B$3,0) -> 0 | E13: =C13-ROW()*0.0001 -> -0.0013
A14: Systems | B14: Linux | C14: =COUNTIFS('01 - Job Database'!$C$3:$C$1000,"<>",'01 - Job Database'!$W$3:$W$1000,"<>Yes",'01 - Job Database'!$AF$3:$AF$1000,"Yes") -> 0 | D14: =IFERROR(C14/'03 - Skill Intelligence'!$B$3,0) -> 0 | E14: =C14-ROW()*0.0001 -> -0.0014
A15: Systems | B15: Operating Systems | C15: =COUNTIFS('01 - Job Database'!$C$3:$C$1000,"<>",'01 - Job Database'!$W$3:$W$1000,"<>Yes",'01 - Job Database'!$AG$3:$AG$1000,"Yes") -> 0 | D15: =IFERROR(C15/'03 - Skill Intelligence'!$B$3,0) -> 0 | E15: =C15-ROW()*0.0001 -> -0.0015
A16: Systems | B16: Multithreading & Concurrency | C16: =COUNTIFS('01 - Job Database'!$C$3:$C$1000,"<>",'01 - Job Database'!$W$3:$W$1000,"<>Yes",'01 - Job Database'!$AH$3:$AH$1000,"Yes") -> 1 | D16: =IFERROR(C16/'03 - Skill Intelligence'!$B$3,0) -> 1 | E16: =C16-ROW()*0.0001 -> 0.9984
A17: Systems | B17: Networking | C17: =COUNTIFS('01 - Job Database'!$C$3:$C$1000,"<>",'01 - Job Database'!$W$3:$W$1000,"<>Yes",'01 - Job Database'!$AI$3:$AI$1000,"Yes") -> 0 | D17: =IFERROR(C17/'03 - Skill Intelligence'!$B$3,0) -> 0 | E17: =C17-ROW()*0.0001 -> -0.0017
A18: Systems | B18: Distributed Systems | C18: =COUNTIFS('01 - Job Database'!$C$3:$C$1000,"<>",'01 - Job Database'!$W$3:$W$1000,"<>Yes",'01 - Job Database'!$AJ$3:$AJ$1000,"Yes") -> 1 | D18: =IFERROR(C18/'03 - Skill Intelligence'!$B$3,0) -> 1 | E18: =C18-ROW()*0.0001 -> 0.9982
A19: Systems | B19: Compilers | C19: =COUNTIFS('01 - Job Database'!$C$3:$C$1000,"<>",'01 - Job Database'!$W$3:$W$1000,"<>Yes",'01 - Job Database'!$AK$3:$AK$1000,"Yes") -> 0 | D19: =IFERROR(C19/'03 - Skill Intelligence'!$B$3,0) -> 0 | E19: =C19-ROW()*0.0001 -> -0.0019
A20: Cloud/Infra | B20: AWS | C20: =COUNTIFS('01 - Job Database'!$C$3:$C$1000,"<>",'01 - Job Database'!$W$3:$W$1000,"<>Yes",'01 - Job Database'!$AL$3:$AL$1000,"Yes") -> 1 | D20: =IFERROR(C20/'03 - Skill Intelligence'!$B$3,0) -> 1 | E20: =C20-ROW()*0.0001 -> 0.998
A21: Cloud/Infra | B21: Azure | C21: =COUNTIFS('01 - Job Database'!$C$3:$C$1000,"<>",'01 - Job Database'!$W$3:$W$1000,"<>Yes",'01 - Job Database'!$AM$3:$AM$1000,"Yes") -> 0 | D21: =IFERROR(C21/'03 - Skill Intelligence'!$B$3,0) -> 0 | E21: =C21-ROW()*0.0001 -> -0.0021
A22: Cloud/Infra | B22: GCP | C22: =COUNTIFS('01 - Job Database'!$C$3:$C$1000,"<>",'01 - Job Database'!$W$3:$W$1000,"<>Yes",'01 - Job Database'!$AN$3:$AN$1000,"Yes") -> 0 | D22: =IFERROR(C22/'03 - Skill Intelligence'!$B$3,0) -> 0 | E22: =C22-ROW()*0.0001 -> -0.0022
A23: Cloud/Infra | B23: Kubernetes | C23: =COUNTIFS('01 - Job Database'!$C$3:$C$1000,"<>",'01 - Job Database'!$W$3:$W$1000,"<>Yes",'01 - Job Database'!$AO$3:$AO$1000,"Yes") -> 0 | D23: =IFERROR(C23/'03 - Skill Intelligence'!$B$3,0) -> 0 | E23: =C23-ROW()*0.0001 -> -0.0023
A24: Cloud/Infra | B24: Docker | C24: =COUNTIFS('01 - Job Database'!$C$3:$C$1000,"<>",'01 - Job Database'!$W$3:$W$1000,"<>Yes",'01 - Job Database'!$AP$3:$AP$1000,"Yes") -> 0 | D24: =IFERROR(C24/'03 - Skill Intelligence'!$B$3,0) -> 0 | E24: =C24-ROW()*0.0001 -> -0.0024
A25: Cloud/Infra | B25: Terraform | C25: =COUNTIFS('01 - Job Database'!$C$3:$C$1000,"<>",'01 - Job Database'!$W$3:$W$1000,"<>Yes",'01 - Job Database'!$AQ$3:$AQ$1000,"Yes") -> 0 | D25: =IFERROR(C25/'03 - Skill Intelligence'!$B$3,0) -> 0 | E25: =C25-ROW()*0.0001 -> -0.0025
A26: Cloud/Infra | B26: CI/CD | C26: =COUNTIFS('01 - Job Database'!$C$3:$C$1000,"<>",'01 - Job Database'!$W$3:$W$1000,"<>Yes",'01 - Job Database'!$AR$3:$AR$1000,"Yes") -> 0 | D26: =IFERROR(C26/'03 - Skill Intelligence'!$B$3,0) -> 0 | E26: =C26-ROW()*0.0001 -> -0.0026
A27: Data/ML/AI | B27: Data Structures & Algorithms | C27: =COUNTIFS('01 - Job Database'!$C$3:$C$1000,"<>",'01 - Job Database'!$W$3:$W$1000,"<>Yes",'01 - Job Database'!$AS$3:$AS$1000,"Yes") -> 0 | D27: =IFERROR(C27/'03 - Skill Intelligence'!$B$3,0) -> 0 | E27: =C27-ROW()*0.0001 -> -0.0027
A28: Data/ML/AI | B28: Machine Learning | C28: =COUNTIFS('01 - Job Database'!$C$3:$C$1000,"<>",'01 - Job Database'!$W$3:$W$1000,"<>Yes",'01 - Job Database'!$AT$3:$AT$1000,"Yes") -> 1 | D28: =IFERROR(C28/'03 - Skill Intelligence'!$B$3,0) -> 1 | E28: =C28-ROW()*0.0001 -> 0.9972
A29: Data/ML/AI | B29: Deep Learning | C29: =COUNTIFS('01 - Job Database'!$C$3:$C$1000,"<>",'01 - Job Database'!$W$3:$W$1000,"<>Yes",'01 - Job Database'!$AU$3:$AU$1000,"Yes") -> 1 | D29: =IFERROR(C29/'03 - Skill Intelligence'!$B$3,0) -> 1 | E29: =C29-ROW()*0.0001 -> 0.9971
A30: Data/ML/AI | B30: PyTorch/TensorFlow | C30: =COUNTIFS('01 - Job Database'!$C$3:$C$1000,"<>",'01 - Job Database'!$W$3:$W$1000,"<>Yes",'01 - Job Database'!$AV$3:$AV$1000,"Yes") -> 0 | D30: =IFERROR(C30/'03 - Skill Intelligence'!$B$3,0) -> 0 | E30: =C30-ROW()*0.0001 -> -0.003
A31: Data/ML/AI | B31: LLMs / NLP | C31: =COUNTIFS('01 - Job Database'!$C$3:$C$1000,"<>",'01 - Job Database'!$W$3:$W$1000,"<>Yes",'01 - Job Database'!$AW$3:$AW$1000,"Yes") -> 1 | D31: =IFERROR(C31/'03 - Skill Intelligence'!$B$3,0) -> 1 | E31: =C31-ROW()*0.0001 -> 0.9969
A32: Data/ML/AI | B32: CUDA / GPU Programming | C32: =COUNTIFS('01 - Job Database'!$C$3:$C$1000,"<>",'01 - Job Database'!$W$3:$W$1000,"<>Yes",'01 - Job Database'!$AX$3:$AX$1000,"Yes") -> 0 | D32: =IFERROR(C32/'03 - Skill Intelligence'!$B$3,0) -> 0 | E32: =C32-ROW()*0.0001 -> -0.0032
A33: Data/ML/AI | B33: Big Data (Spark/Hadoop) | C33: =COUNTIFS('01 - Job Database'!$C$3:$C$1000,"<>",'01 - Job Database'!$W$3:$W$1000,"<>Yes",'01 - Job Database'!$AY$3:$AY$1000,"Yes") -> 0 | D33: =IFERROR(C33/'03 - Skill Intelligence'!$B$3,0) -> 0 | E33: =C33-ROW()*0.0001 -> -0.0033
A34: Architecture | B34: System Design | C34: =COUNTIFS('01 - Job Database'!$C$3:$C$1000,"<>",'01 - Job Database'!$W$3:$W$1000,"<>Yes",'01 - Job Database'!$AZ$3:$AZ$1000,"Yes") -> 1 | D34: =IFERROR(C34/'03 - Skill Intelligence'!$B$3,0) -> 1 | E34: =C34-ROW()*0.0001 -> 0.9966
A35: Architecture | B35: Microservices / API Design | C35: =COUNTIFS('01 - Job Database'!$C$3:$C$1000,"<>",'01 - Job Database'!$W$3:$W$1000,"<>Yes",'01 - Job Database'!$BA$3:$BA$1000,"Yes") -> 1 | D35: =IFERROR(C35/'03 - Skill Intelligence'!$B$3,0) -> 1 | E35: =C35-ROW()*0.0001 -> 0.9965
A36: Architecture | B36: Security / Cryptography | C36: =COUNTIFS('01 - Job Database'!$C$3:$C$1000,"<>",'01 - Job Database'!$W$3:$W$1000,"<>Yes",'01 - Job Database'!$BB$3:$BB$1000,"Yes") -> 1 | D36: =IFERROR(C36/'03 - Skill Intelligence'!$B$3,0) -> 1 | E36: =C36-ROW()*0.0001 -> 0.9964
A37: Architecture | B37: Testing / QA | C37: =COUNTIFS('01 - Job Database'!$C$3:$C$1000,"<>",'01 - Job Database'!$W$3:$W$1000,"<>Yes",'01 - Job Database'!$BC$3:$BC$1000,"Yes") -> 1 | D37: =IFERROR(C37/'03 - Skill Intelligence'!$B$3,0) -> 1 | E37: =C37-ROW()*0.0001 -> 0.9963
A38: Newly Discovered | B38: HTML | C38: =COUNTIFS('01 - Job Database'!$C$3:$C$1000,"<>",'01 - Job Database'!$W$3:$W$1000,"<>Yes",'01 - Job Database'!$CM$3:$CM$1000,"Yes") -> 0 | D38: =IFERROR(C38/'03 - Skill Intelligence'!$B$3,0) -> 0 | E38: =C38-ROW()*0.0001 -> -0.0038
A39: Newly Discovered | B39: CSS | C39: =COUNTIFS('01 - Job Database'!$C$3:$C$1000,"<>",'01 - Job Database'!$W$3:$W$1000,"<>Yes",'01 - Job Database'!$CN$3:$CN$1000,"Yes") -> 0 | D39: =IFERROR(C39/'03 - Skill Intelligence'!$B$3,0) -> 0 | E39: =C39-ROW()*0.0001 -> -0.0039
A40: Newly Discovered | B40: MySQL | C40: =COUNTIFS('01 - Job Database'!$C$3:$C$1000,"<>",'01 - Job Database'!$W$3:$W$1000,"<>Yes",'01 - Job Database'!$CO$3:$CO$1000,"Yes") -> 0 | D40: =IFERROR(C40/'03 - Skill Intelligence'!$B$3,0) -> 0 | E40: =C40-ROW()*0.0001 -> -0.004
